Workbook

Sheet emp_pivot
K2: Count of EmployeeID | L2: Column Labels | P2: Count of EmployeeID | Q2: Column Labels | U2: Count of EmployeeID | V2: Column Labels | Z2: Count of EmployeeID | AA2: Column Labels | AE2: Count of EmployeeID | AF2: Column Labels | AJ2: Count of EmployeeID | AK2: Column Labels
A3: Count of EmployeeID | B3: Column Labels | K3: Row Labels | L3: No | M3: Yes | N3: Grand Total | P3: Row Labels | Q3: No | R3: Yes | S3: Grand Total | U3: Row Labels | V3: No | W3: Yes | X3: Grand Total | Z3: Row Labels | AA3: No | AB3: Yes | AC3: Grand Total | AE3: Row Labels | AF3: No | AG3: Yes | AH3: Grand Total | AJ3: Row Labels | AK3: No | AL3: Yes | AM3: Grand Total | AO3: Count of EmployeeID | AP3: Column Labels
A4: Row Labels | B4: No | C4: Yes | D4: Grand Total | F4: Count of EmployeeID | G4: Column Labels | K4: 1 | L4: 493 | M4: 73 | N4: 566 | P4: Divorced | Q4: 457 | R4: 48 | S4: 505 | U4: 1 | V4: 80 | W4: 10 | X4: 90 | Z4: 0 | AA4: 431 | AB4: 65 | AC4: 496 | AE4: 1 | AF4: 693 | AG4: 93 | AH4: 786 | AJ4: 0 | AK4: 392 | AL4: 44 | AM4: 436 | AO4: Row Labels | AP4: No | AQ4: Yes | AR4: Grand Total
A5: Developer | B5: 118 | C5: 11 | D5: 129 | F5: Row Labels | G5: No | H5: Yes | I5: Grand Total | K5: 2 | L5: 1006 | M5: 152 | N5: 1158 | P5: Married | Q5: 1324 | R5: 191 | S5: 1515 | U5: 2 | V5: 87 | W5: 11 | X5: 98 | Z5: 1 | AA5: 190 | AB5: 32 | AC5: 222 | AE5: 2 | AF5: 636 | AG5: 98 | AH5: 734 | AJ5: 1 | AK5: 372 | AL5: 59 | AM5: 431 | AO5: 18-25 | AP5: 296 | AQ5: 56 | AR5: 352
A6: Finance Analyst | B6: 145 | C6: 25 | D6: 170 | F6: No | G6: 1957 | H6: 225 | I6: 2182 | K6: 3 | L6: 716 | M6: 87 | N6: 803 | P6: Single | Q6: 843 | R6: 137 | S6: 980 | U6: 3 | V6: 89 | W6: 8 | X6: 97 | Z6: 2 | AA6: 207 | AB6: 36 | AC6: 243 | AE6: 3 | AF6: 662 | AG6: 84 | AH6: 746 | AJ6: 2 | AK6: 397 | AL6: 49 | AM6: 446 | AO6: 26-35 | AP6: 666 | AQ6: 102 | AR6: 768
A7: Finance Manager | B7: 133 | C7: 24 | D7: 157 | F7: Yes | G7: 667 | H7: 151 | I7: 818 | K7: 4 | L7: 332 | M7: 50 | N7: 382 | P7: Grand Total | Q7: 2624 | R7: 376 | S7: 3000 | U7: 4 | V7: 97 | W7: 8 | X7: 105 | Z7: 3 | AA7: 251 | AB7: 22 | AC7: 273 | AE7: 4 | AF7: 633 | AG7: 101 | AH7: 734 | AJ7: 3 | AK7: 367 | AL7: 61 | AM7: 428 | AO7: 36-45 | AP7: 655 | AQ7: 96 | AR7: 751
A8: Human Resources | B8: 101 | C8: 12 | D8: 113 | F8: Grand Total | G8: 2624 | H8: 376 | I8: 3000 | K8: 5 | L8: 77 | M8: 14 | N8: 91 | U8: 5 | V8: 94 | W8: 18 | X8: 112 | Z8: 4 | AA8: 264 | AB8: 40 | AC8: 304 | AE8: Grand Total | AF8: 2624 | AG8: 376 | AH8: 3000 | AJ8: 4 | AK8: 340 | AL8: 60 | AM8: 400 | AO8: 46-55 | AP8: 687 | AQ8: 89 | AR8: 776
A9: IT Manager | B9: 91 | C9: 16 | D9: 107 | K9: Grand Total | L9: 2624 | M9: 376 | N9: 3000 | P9: Count of EmployeeID | Q9: Column Labels | U9: 6 | V9: 95 | W9: 9 | X9: 104 | Z9: 5 | AA9: 283 | AB9: 40 | AC9: 323 | AJ9: 5 | AK9: 389 | AL9: 44 | AM9: 433 | AO9: 56-65 | AP9: 320 | AQ9: 33 | AR9: 353
A10: IT Support | B10: 112 | C10: 17 | D10: 129 | P10: Row Labels | Q10: No | R10: Yes | S10: Grand Total | U10: 7 | V10: 79 | W10: 12 | X10: 91 | Z10: 6 | AA10: 249 | AB10: 37 | AC10: 286 | AE10: Count of EmployeeID | AF10: Column Labels | AJ10: 6 | AK10: 367 | AL10: 59 | AM10: 426 | AO10: Grand Total | AP10: 2624 | AQ10: 376 | AR10: 3000
A11: Laboratory Technician | B11: 262 | C11: 34 | D11: 296 | F11: Count of EmployeeID | G11: Column Labels | K11: Count of EmployeeID | L11: Column Labels | P11: Bachelor's | Q11: 1251 | R11: 180 | S11: 1431 | U11: 8 | V11: 96 | W11: 14 | X11: 110 | Z11: 7 | AA11: 200 | AB11: 25 | AC11: 225 | AE11: Row Labels | AF11: No | AG11: Yes | AH11: Grand Total | AJ11: Grand Total | AK11: 2624 | AL11: 376 | AM11: 3000
A12: Logistics Specialist | B12: 134 | C12: 22 | D12: 156 | F12: Row Labels | G12: No | H12: Yes | I12: Grand Total | K12: Row Labels | L12: No | M12: Yes | N12: Grand Total | P12: Doctorate | Q12: 214 | R12: 25 | S12: 239 | U12: 9 | V12: 81 | W12: 16 | X12: 97 | Z12: 8 | AA12: 158 | AB12: 23 | AC12: 181 | AE12: 0 | AF12: 105 | AG12: 18 | AH12: 123
A13: Manager | B13: 321 | C13: 38 | D13: 359 | F13: 1 | G13: 628 | H13: 112 | I13: 740 | K13: Female | L13: 1091 | M13: 172 | N13: 1263 | P13: High School | Q13: 258 | R13: 37 | S13: 295 | U13: 10 | V13: 87 | W13: 9 | X13: 96 | Z13: 9 | AA13: 129 | AB13: 17 | AC13: 146 | AE13: 1 | AF13: 43 | AG13: 8 | AH13: 51 | AJ13: Count of EmployeeID | AK13: Column Labels
A14: Operations Coordinator | B14: 148 | C14: 19 | D14: 167 | F14: 2 | G14: 710 | H14: 90 | I14: 800 | K14: Male | L14: 1533 | M14: 204 | N14: 1737 | P14: Master's | Q14: 901 | R14: 134 | S14: 1035 | U14: 11 | V14: 83 | W14: 6 | X14: 89 | Z14: 10 | AA14: 97 | AB14: 19 | AC14: 116 | AE14: 2 | AF14: 49 | AG14: 14 | AH14: 63 | AJ14: Row Labels | AK14: No | AL14: Yes | AM14: Grand Total
A15: Operations Manager | B15: 146 | C15: 23 | D15: 169 | F15: 3 | G15: 687 | H15: 90 | I15: 777 | K15: Grand Total | L15: 2624 | M15: 376 | N15: 3000 | P15: Grand Total | Q15: 2624 | R15: 376 | S15: 3000 | U15: 12 | V15: 85 | W15: 11 | X15: 96 | Z15: 11 | AA15: 65 | AB15: 8 | AC15: 73 | AE15: 3 | AF15: 64 | AG15: 4 | AH15: 68 | AJ15: 1 | AK15: 644 | AL15: 101 | AM15: 745
A16: Research Director | B16: 247 | C16: 31 | D16: 278 | F16: 4 | G16: 599 | H16: 84 | I16: 683 | U16: 13 | V16: 105 | W16: 10 | X16: 115 | Z16: 12 | AA16: 40 | AB16: 7 | AC16: 47 | AE16: 4 | AF16: 72 | AG16: 18 | AH16: 90 | AJ16: 2 | AK16: 649 | AL16: 96 | AM16: 745
A17: Research Scientist | B17: 277 | C17: 43 | D17: 320 | F17: Grand Total | G17: 2624 | H17: 376 | I17: 3000 | K17: Count of EmployeeID | L17: Column Labels | P17: Count of EmployeeID | Q17: Column Labels | U17: 14 | V17: 96 | W17: 8 | X17: 104 | Z17: 13 | AA17: 27 | AB17: 3 | AC17: 30 | AE17: 5 | AF17: 76 | AG17: 8 | AH17: 84 | AJ17: 3 | AK17: 648 | AL17: 88 | AM17: 736
A18: Sales Executive | B18: 204 | C18: 34 | D18: 238 | K18: Row Labels | L18: No | M18: Yes | N18: Grand Total | P18: Row Labels | Q18: No | R18: Yes | S18: Grand Total | U18: 15 | V18: 85 | W18: 6 | X18: 91 | Z18: 14 | AA18: 21 | AB18: 2 | AC18: 23 | AE18: 6 | AF18: 89 | AG18: 15 | AH18: 104 | AJ18: 4 | AK18: 683 | AL18: 91 | AM18: 774
A19: Sales Representative | B19: 185 | C19: 27 | D19: 212 | F19: Count of EmployeeID | G19: Column Labels | K19: 21 | L19: 56 | M19: 11 | N19: 67 | P19: Human Resources | Q19: 406 | R19: 62 | S19: 468 | U19: 16 | V19: 99 | W19: 15 | X19: 114 | Z19: 15 | AA19: 7 | AC19: 7 | AE19: 7 | AF19: 87 | AG19: 18 | AH19: 105 | AJ19: Grand Total | AK19: 2624 | AL19: 376 | AM19: 3000
A20: Grand Total | B20: 2624 | C20: 376 | D20: 3000 | F20: Row Labels | G20: No | H20: Yes | I20: Grand Total | K20: 22 | L20: 58 | M20: 15 | N20: 73 | P20: Life Sciences | Q20: 455 | R20: 57 | S20: 512 | U20: 17 | V20: 74 | W20: 12 | X20: 86 | Z20: 16 | AA20: 3 | AC20: 3 | AE20: 8 | AF20: 92 | AG20: 16 | AH20: 108
F21: 1 | G21: 599 | H21: 105 | I21: 704 | K21: 23 | L21: 65 | M21: 10 | N21: 75 | P21: Marketing | Q21: 418 | R21: 65 | S21: 483 | U21: 18 | V21: 94 | W21: 9 | X21: 103 | Z21: 17 | AA21: 2 | AC21: 2 | AE21: 9 | AF21: 87 | AG21: 10 | AH21: 97 | AJ21: Count of EmployeeID | AK21: Column Labels
F22: 2 | G22: 693 | H22: 93 | I22: 786 | K22: 24 | L22: 48 | M22: 8 | N22: 56 | P22: Medical | Q22: 457 | R22: 61 | S22: 518 | U22: 19 | V22: 89 | W22: 18 | X22: 107 | Z22: Grand Total | AA22: 2624 | AB22: 376 | AC22: 3000 | AE22: 10 | AF22: 90 | AG22: 14 | AH22: 104 | AJ22: Row Labels | AK22: No | AL22: Yes | AM22: Grand Total
F23: 3 | G23: 643 | H23: 91 | I23: 734 | K23: 25 | L23: 69 | M23: 12 | N23: 81 | P23: Other | Q23: 424 | R23: 57 | S23: 481 | U23: 20 | V23: 85 | W23: 15 | X23: 100 | AE23: 11 | AF23: 110 | AG23: 15 | AH23: 125 | AJ23: 3 | AK23: 2056 | AL23: 290 | AM23: 2346
F24: 4 | G24: 689 | H24: 87 | I24: 776 | K24: 26 | L24: 64 | M24: 10 | N24: 74 | P24: Technical Degree | Q24: 449 | R24: 74 | S24: 523 | U24: 21 | V24: 97 | W24: 18 | X24: 115 | Z24: Count of EmployeeID | AA24: Column Labels | AE24: 12 | AF24: 94 | AG24: 11 | AH24: 105 | AJ24: 4 | AK24: 568 | AL24: 86 | AM24: 654
F25: Grand Total | G25: 2624 | H25: 376 | I25: 3000 | K25: 27 | L25: 64 | M25: 12 | N25: 76 | P25: Unknown | Q25: 15 | S25: 15 | U25: 22 | V25: 82 | W25: 6 | X25: 88 | Z25: Row Labels | AA25: No | AB25: Yes | AC25: Grand Total | AE25: 13 | AF25: 110 | AG25: 23 | AH25: 133 | AJ25: Grand Total | AK25: 2624 | AL25: 376 | AM25: 3000
K26: 28 | L26: 58 | M26: 10 | N26: 68 | P26: Grand Total | Q26: 2624 | R26: 376 | S26: 3000 | U26: 23 | V26: 70 | W26: 14 | X26: 84 | Z26: 0 | AA26: 911 | AB26: 132 | AC26: 1043 | AE26: 14 | AF26: 105 | AG26: 18 | AH26: 123
F27: Count of EmployeeID | G27: Column Labels | K27: 29 | L27: 66 | M27: 9 | N27: 75 | U27: 24 | V27: 95 | W27: 11 | X27: 106 | Z27: 1 | AA27: 428 | AB27: 69 | AC27: 497 | AE27: 15 | AF27: 90 | AG27: 16 | AH27: 106
F28: Row Labels | G28: No | H28: Yes | I28: Grand Total | K28: 30 | L28: 69 | M28: 14 | N28: 83 | P28: Count of EmployeeID | Q28: Column Labels | U28: 25 | V28: 86 | W28: 11 | X28: 97 | Z28: 2 | AA28: 395 | AB28: 77 | AC28: 472 | AE28: 16 | AF28: 107 | AG28: 17 | AH28: 124 | AJ28: Count of EmployeeID | AK28: Column Labels
F29: Non-Travel | G29: 310 | H29: 39 | I29: 349 | K29: 31 | L29: 59 | M29: 9 | N29: 68 | P29: Row Labels | Q29: No | R29: Yes | S29: Grand Total | U29: 26 | V29: 88 | W29: 21 | X29: 109 | Z29: 3 | AA29: 355 | AB29: 44 | AC29: 399 | AE29: 17 | AF29: 96 | AG29: 14 | AH29: 110 | AJ29: Row Labels | AK29: No | AL29: Yes | AM29: Grand Total
F30: Travel_Frequently | G30: 389 | H30: 76 | I30: 465 | K30: 32 | L30: 72 | M30: 12 | N30: 84 | P30: 1 | Q30: 644 | R30: 101 | S30: 745 | U30: 27 | V30: 85 | W30: 11 | X30: 96 | Z30: 4 | AA30: 272 | AB30: 32 | AC30: 304 | AE30: 18 | AF30: 108 | AG30: 12 | AH30: 120 | AJ30: Non-Travel | AK30: 310 | AL30: 39 | AM30: 349
F31: Travel_Rarely | G31: 1925 | H31: 261 | I31: 2186 | K31: 33 | L31: 70 | M31: 8 | N31: 78 | P31: 2 | Q31: 649 | R31: 96 | S31: 745 | U31: 28 | V31: 81 | W31: 22 | X31: 103 | Z31: 5 | AA31: 154 | AB31: 11 | AC31: 165 | AE31: 19 | AF31: 104 | AG31: 15 | AH31: 119 | AJ31: Travel_Frequently | AK31: 389 | AL31: 76 | AM31: 465
F32: Grand Total | G32: 2624 | H32: 376 | I32: 3000 | K32: 34 | L32: 73 | M32: 16 | N32: 89 | P32: 3 | Q32: 648 | R32: 88 | S32: 736 | U32: 29 | V32: 80 | W32: 19 | X32: 99 | Z32: 6 | AA32: 70 | AB32: 8 | AC32: 78 | AE32: 20 | AF32: 115 | AG32: 14 | AH32: 129 | AJ32: Travel_Rarely | AK32: 1925 | AL32: 261 | AM32: 2186
K33: 35 | L33: 71 | M33: 2 | N33: 73 | P33: 4 | Q33: 683 | R33: 91 | S33: 774 | U33: 30 | V33: 80 | W33: 18 | X33: 98 | Z33: 7 | AA33: 30 | AB33: 2 | AC33: 32 | AE33: 21 | AF33: 88 | AG33: 8 | AH33: 96 | AJ33: Grand Total | AK33: 2624 | AL33: 376 | AM33: 3000
K34: 36 | L34: 53 | M34: 8 | N34: 61 | P34: Grand Total | Q34: 2624 | R34: 376 | S34: 3000 | U34: Grand Total | V34: 2624 | W34: 376 | X34: 3000 | Z34: 8 | AA34: 8 | AB34: 1 | AC34: 9 | AE34: 22 | AF34: 96 | AG34: 11 | AH34: 107
K35: 37 | L35: 68 | M35: 12 | N35: 80 | Z35: 9 | AA35: 1 | AC35: 1 | AE35: 23 | AF35: 86 | AG35: 12 | AH35: 98 | AJ35: Count of EmployeeID | AK35: Column Labels
K36: 38 | L36: 71 | M36: 13 | N36: 84 | P36: Count of EmployeeID | Q36: Column Labels | U36: Count of EmployeeID | V36: Column Labels | Z36: Grand Total | AA36: 2624 | AB36: 376 | AC36: 3000 | AE36: 24 | AF36: 85 | AG36: 9 | AH36: 94 | AJ36: Row Labels | AK36: No | AL36: Yes | AM36: Grand Total
K37: 39 | L37: 67 | M37: 11 | N37: 78 | P37: Row Labels | Q37: No | R37: Yes | S37: Grand Total | U37: Row Labels | V37: No | W37: Yes | X37: Grand Total | AE37: 25 | AF37: 83 | AG37: 6 | AH37: 89 | AJ37: Female | AK37: 1091 | AL37: 172 | AM37: 1263
K38: 40 | L38: 54 | M38: 5 | N38: 59 | P38: 3 | Q38: 2056 | R38: 290 | S38: 2346 | U38: 0 | V38: 431 | W38: 65 | X38: 496 | Z38: Count of EmployeeID | AA38: Column Labels | AE38: 26 | AF38: 50 | AG38: 5 | AH38: 55 | AJ38: Male | AK38: 1533 | AL38: 204 | AM38: 1737
K39: 41 | L39: 72 | M39: 8 | N39: 80 | P39: 4 | Q39: 568 | R39: 86 | S39: 654 | U39: 1 | V39: 190 | W39: 32 | X39: 222 | Z39: Row Labels | AA39: No | AB39: Yes | AC39: Grand Total | AE39: 27 | AF39: 59 | AG39: 8 | AH39: 67 | AJ39: Grand Total | AK39: 2624 | AL39: 376 | AM39: 3000
K40: 42 | L40: 59 | M40: 10 | N40: 69 | P40: Grand Total | Q40: 2624 | R40: 376 | S40: 3000 | U40: 2 | V40: 207 | W40: 36 | X40: 243 | Z40: 0 | AA40: 1049 | AB40: 144 | AC40: 1193 | AE40: 28 | AF40: 46 | AG40: 8 | AH40: 54
K41: 43 | L41: 67 | M41: 11 | N41: 78 | U41: 3 | V41: 251 | W41: 22 | X41: 273 | Z41: 1 | AA41: 489 | AB41: 71 | AC41: 560 | AE41: 29 | AF41: 33 | AG41: 3 | AH41: 36
...

Sheet Employees
A1: EmployeeID | B1: Age | C1: Gender | D1: Department | E1: JobRole | F1: Education | G1: EducationField | H1: JobLevel | I1: MonthlyIncome | J1: HourlyRate | K1: OverTime | L1: JobSatisfaction | M1: EnvironmentSatisfaction | N1: WorkLifeBalance | O1: YearsAtCompany | P1: YearsInCurrentRole | Q1: YearsSinceLastPromotion | R1: YearsWithCurrentManager | S1: TotalWorkingYears | T1: TrainingTimesLastYear | U1: PerformanceRating | V1: BusinessTravel | W1: DistanceFromHome | X1: MaritalStatus | Y1: JobInvolvement | Z1: Attrition | AA1: HireDate | AB1: ExitDate | AC1: City | AD1: State | AE1: Missing Check | AF1: city clean | AG1: Monthly Income Clean | AH1: AGE GROUP CLEAN
A2: EMP10001 | B2: 38 | C2: Male | D2: IT | E2: Developer | F2: Master's | G2: Other | H2: 3 | I2: 10576 | J2: 36 | K2: No | L2: 4 | M2: 4 | N2: 2 | O2: 10 | P2: 5 | Q2: 7 | R2: 0 | S2: 16 | T2: 0 | U2: 3 | V2: Travel_Rarely | W2: 2 | X2: Married | Y2: 3 | Z2: No | AA2: 42158 | AC2: Ahmedabad | AD2: Gujarat | AE2: =COUNTBLANK(A2:AE2) -> 0 | AF2: =PROPER(UPPER(TRIM(Table1[[#This Row],[City]]))) -> Ahmedabad | AG2: =IF(ISBLANK(I2),AVERAGE($I$2:$I$3001),I2) -> 10576 | AH2: =_xlfn.IFS(Table1[[#This Row],[Age]]<=25,"18-25",Table1[[#This Row],[Age]]<=35,"26-35",Table1[[#This Row],[Age]]<=45,"36-45",Table1[[#This Row],[Age]]<=55,"46-55",Table1[[#This Row],[Age]]<=65,"56-65") -> 36-45
A3: EMP10002 | B3: 21 | C3: Male | D3: Research & Development | E3: Research Director | F3: Bachelor's | G3: Technical Degree | H3: 2 | I3: 6848 | J3: 75 | K3: Yes | L3: 4 | M3: 1 | N3: 2 | O3: 4 | P3: 4 | Q3: 2 | R3: 2 | S3: 7 | T3: 3 | U3: 3 | V3: Travel_Rarely | W3: 21 | X3: Single | Y3: 4 | Z3: Yes | AA3: 45381 | AB3: 45610 | AC3: Bengaluru | AD3: Karnataka | AE3: =COUNTBLANK(A3:AE3) -> 0 | AF3: =PROPER(UPPER(TRIM(Table1[[#This Row],[City]]))) -> Bengaluru | AG3: =IF(ISBLANK(I3),AVERAGE($I$2:$I$3001),I3) -> 6848 | AH3: =_xlfn.IFS(Table1[[#This Row],[Age]]<=25,"18-25",Table1[[#This Row],[Age]]<=35,"26-35",Table1[[#This Row],[Age]]<=45,"36-45",Table1[[#This Row],[Age]]<=55,"46-55",Table1[[#This Row],[Age]]<=65,"56-65") -> 18-25
A4: EMP10003 | B4: 47 | C4: Male | D4: Operations | E4: Operations Coordinator | F4: Bachelor's | G4: Technical Degree | H4: 2 | I4: 7725 | J4: 56 | K4: No | L4: 1 | M4: 2 | N4: 1 | O4: 0 | P4: 0 | Q4: 0 | R4: 0 | S4: 16 | T4: 0 | U4: 3 | V4: Travel_Rarely | W4: 28 | X4: Single | Y4: 4 | Z4: No | AA4: 43439 | AC4: Chennai | AD4: Tamil Nadu | AE4: =COUNTBLANK(A4:AE4) -> 0 | AF4: =PROPER(UPPER(TRIM(Table1[[#This Row],[City]]))) -> Chennai | AG4: =IF(ISBLANK(I4),AVERAGE($I$2:$I$3001),I4) -> 7725 | AH4: =_xlfn.IFS(Table1[[#This Row],[Age]]<=25,"18-25",Table1[[#This Row],[Age]]<=35,"26-35",Table1[[#This Row],[Age]]<=45,"36-45",Table1[[#This Row],[Age]]<=55,"46-55",Table1[[#This Row],[Age]]<=65,"56-65") -> 46-55
A5: EMP10004 | B5: 39 | C5: Male | D5: Finance | E5: Finance Manager | F5: High School | G5: Marketing | H5: 2 | I5: 9420 | J5: 34 | K5: No | L5: 3 | M5: 3 | N5: 1 | O5: 8 | P5: 2 | Q5: 2 | R5: 4 | S5: 13 | T5: 5 | U5: 4 | V5: Non-Travel | W5: 7 | X5: Divorced | Y5: 3 | Z5: No | AA5: 45569 | AC5: Chennai | AD5: Tamil Nadu | AE5: =COUNTBLANK(A5:AE5) -> 0 | AF5: =PROPER(UPPER(TRIM(Table1[[#This Row],[City]]))) -> Chennai | AG5: =IF(ISBLANK(I5),AVERAGE($I$2:$I$3001),I5) -> 9420 | AH5: =_xlfn.IFS(Table1[[#This Row],[Age]]<=25,"18-25",Table1[[#This Row],[Age]]<=35,"26-35",Table1[[#This Row],[Age]]<=45,"36-45",Table1[[#This Row],[Age]]<=55,"46-55",Table1[[#This Row],[Age]]<=65,"56-65") -> 36-45
A6: EMP10005 | B6: 51 | C6: Male | D6: Sales | E6: Sales Representative | F6: High School | G6: Other | H6: 1 | I6: 7293 | J6: 75 | K6: Yes | L6: 2 | M6: 3 | N6: 3 | O6: 1 | P6: 0 | Q6: 1 | R6: 1 | S6: 33 | T6: 4 | U6: 4 | V6: Travel_Frequently | W6: 24 | X6: Single | Y6: 4 | Z6: Yes | AA6: 42989 | AB6: 45141 | AC6: Pune | AD6: Maharashtra | AE6: =COUNTBLANK(A6:AE6) -> 0 | AF6: =PROPER(UPPER(TRIM(Table1[[#This Row],[City]]))) -> Pune | AG6: =IF(ISBLANK(I6),AVERAGE($I$2:$I$3001),I6) -> 7293 | AH6: =_xlfn.IFS(Table1[[#This Row],[Age]]<=25,"18-25",Table1[[#This Row],[Age]]<=35,"26-35",Table1[[#This Row],[Age]]<=45,"36-45",Table1[[#This Row],[Age]]<=55,"46-55",Table1[[#This Row],[Age]]<=65,"56-65") -> 46-55
A7: EMP10006 | B7: 45 | C7: Male | D7: Operations | E7: Operations Manager | F7: Master's | G7: Life Sciences | H7: 3 | I7: 10255 | J7: 29 | K7: No | L7: 2 | M7: 3 | N7: 4 | O7: 10 | P7: 2 | Q7: 4 | R7: 3 | S7: 21 | T7: 3 | U7: 3 | V7: Travel_Rarely | W7: 7 | X7: Married | Y7: 4 | Z7: No | AA7: 43622 | AC7: Bengaluru | AD7: Karnataka | AE7: =COUNTBLANK(A7:AE7) -> 0 | AF7: =PROPER(UPPER(TRIM(Table1[[#This Row],[City]]))) -> Bengaluru | AG7: =IF(ISBLANK(I7),AVERAGE($I$2:$I$3001),I7) -> 10255 | AH7: =_xlfn.IFS(Table1[[#This Row],[Age]]<=25,"18-25",Table1[[#This Row],[Age]]<=35,"26-35",Table1[[#This Row],[Age]]<=45,"36-45",Table1[[#This Row],[Age]]<=55,"46-55",Table1[[#This Row],[Age]]<=65,"56-65") -> 36-45
A8: EMP10007 | B8: 52 | C8: Female | D8: IT | E8: IT Support | F8: Bachelor's | G8: Medical | H8: 1 | I8: 6591 | J8: 113 | K8: Yes | L8: 2 | M8: 3 | N8: 3 | O8: 9 | P8: 7 | Q8: 0 | R8: 1 | S8: 24 | T8: 2 | U8: 4 | V8: Travel_Frequently | W8: 28 | X8: Married | Y8: 2 | Z8: No | AA8: 42422 | AC8: Chennai | AD8: Tamil Nadu | AE8: =COUNTBLANK(A8:AE8) -> 0 | AF8: =PROPER(UPPER(TRIM(Table1[[#This Row],[City]]))) -> Chennai | AG8: =IF(ISBLANK(I8),AVERAGE($I$2:$I$3001),I8) -> 6591 | AH8: =_xlfn.IFS(Table1[[#This Row],[Age]]<=25,"18-25",Table1[[#This Row],[Age]]<=35,"26-35",Table1[[#This Row],[Age]]<=45,"36-45",Table1[[#This Row],[Age]]<=55,"46-55",Table1[[#This Row],[Age]]<=65,"56-65") -> 46-55
A9: EMP10008 | B9: 39 | C9: Female | D9: IT | E9: IT Manager | F9: Bachelor's | G9: Other | H9: 3 | I9: 9847 | J9: 112 | K9: No | L9: 4 | M9: 1 | N9: 3 | O9: 6 | P9: 4 | Q9: 3 | R9: 3 | S9: 17 | T9: 1 | U9: 3 | V9: Travel_Rarely | W9: 11 | X9: Married | Y9: 2 | Z9: No | AA9: 45264 | AC9: Delhi | AD9: Delhi | AE9: =COUNTBLANK(A9:AE9) -> 0 | AF9: =PROPER(UPPER(TRIM(Table1[[#This Row],[City]]))) -> Delhi | AG9: =IF(ISBLANK(I9),AVERAGE($I$2:$I$3001),I9) -> 9847 | AH9: =_xlfn.IFS(Table1[[#This Row],[Age]]<=25,"18-25",Table1[[#This Row],[Age]]<=35,"26-35",Table1[[#This Row],[Age]]<=45,"36-45",Table1[[#This Row],[Age]]<=55,"46-55",Table1[[#This Row],[Age]]<=65,"56-65") -> 36-45
A10: EMP10009 | B10: 21 | C10: Female | D10: Sales | E10: Sales Executive | F10: Master's | G10: Marketing | H10: 2 | I10: 7086 | J10: 93 | K10: Yes | L10: 2 | M10: 4 | N10: 2 | O10: 0 | P10: 0 | Q10: 0 | R10: 0 | S10: 0 | T10: 6 | U10: 3 | V10: Travel_Rarely | W10: 20 | X10: Married | Y10: 1 | Z10: No | AA10: 44828 | AC10: Hyderabad | AD10: Telangana | AE10: =COUNTBLANK(A10:AE10) -> 0 | AF10: =PROPER(UPPER(TRIM(Table1[[#This Row],[City]]))) -> Hyderabad | AG10: =IF(ISBLANK(I10),AVERAGE($I$2:$I$3001),I10) -> 7086 | AH10: =_xlfn.IFS(Table1[[#This Row],[Age]]<=25,"18-25",Table1[[#This Row],[Age]]<=35,"26-35",Table1[[#This Row],[Age]]<=45,"36-45",Table1[[#This Row],[Age]]<=55,"46-55",Table1[[#This Row],[Age]]<=65,"56-65") -> 18-25
A11: EMP10010 | B11: 26 | C11: Female | D11: Research & Development | E11: Research Scientist | F11: High School | G11: Medical | H11: 3 | I11: 6510 | J11: 107 | K11: Yes | L11: 1 | M11: 2 | N11: 4 | O11: 3 | P11: 3 | Q11: 3 | R11: 2 | S11: 3 | T11: 0 | U11: 3 | V11: Travel_Rarely | W11: 29 | X11: Married | Y11: 1 | Z11: No | AA11: 43518 | AC11: Mumbai | AD11: Maharashtra | AE11: =COUNTBLANK(A11:AE11) -> 0 | AF11: =PROPER(UPPER(TRIM(Table1[[#This Row],[City]]))) -> Mumbai | AG11: =IF(ISBLANK(I11),AVERAGE($I$2:$I$3001),I11) -> 6510 | AH11: =_xlfn.IFS(Table1[[#This Row],[Age]]<=25,"18-25",Table1[[#This Row],[Age]]<=35,"26-35",Table1[[#This Row],[Age]]<=45,"36-45",Table1[[#This Row],[Age]]<=55,"46-55",Table1[[#This Row],[Age]]<=65,"56-65") -> 26-35
A12: EMP10011 | B12: 39 | C12: Female | D12: Research & Development | E12: Laboratory Technician | F12: Bachelor's | G12: Marketing | H12: 2 | I12: 7745 | J12: 103 | K12: No | L12: 1 | M12: 4 | N12: 4 | O12: 6 | P12: 3 | Q12: 5 | R12: 6 | S12: 10 | T12: 0 | U12: 3 | V12: Travel_Frequently | W12: 17 | X12: Single | Y12: 2 | Z12: No | AA12: 44417 | AC12: Bengaluru | AD12: Karnataka | AE12: =COUNTBLANK(A12:AE12) -> 0 | AF12: =PROPER(UPPER(TRIM(Table1[[#This Row],[City]]))) -> Bengaluru | AG12: =IF(ISBLANK(I12),AVERAGE($I$2:$I$3001),I12) -> 7745 | AH12: =_xlfn.IFS(Table1[[#This Row],[Age]]<=25,"18-25",Table1[[#This Row],[Age]]<=35,"26-35",Table1[[#This Row],[Age]]<=45,"36-45",Table1[[#This Row],[Age]]<=55,"46-55",Table1[[#This Row],[Age]]<=65,"56-65") -> 36-45
A13: EMP10012 | B13: 36 | C13: Female | D13: Operations | E13: Logistics Specialist | F13: Master's | G13: Medical | H13: 2 | I13: 7080 | J13: 101 | K13: No | L13: 4 | M13: 3 | N13: 4 | O13: 3 | P13: 3 | Q13: 3 | R13: 3 | S13: 13 | T13: 2 | U13: 4 | V13: Travel_Rarely | W13: 14 | X13: Single | Y13: 1 | Z13: No | AA13: 42413 | AC13: Coimbatore | AD13: Tamil Nadu | AE13: =COUNTBLANK(A13:AE13) -> 0 | AF13: =PROPER(UPPER(TRIM(Table1[[#This Row],[City]]))) -> Coimbatore | AG13: =IF(ISBLANK(I13),AVERAGE($I$2:$I$3001),I13) -> 7080 | AH13: =_xlfn.IFS(Table1[[#This Row],[Age]]<=25,"18-25",Table1[[#This Row],[Age]]<=35,"26-35",Table1[[#This Row],[Age]]<=45,"36-45",Table1[[#This Row],[Age]]<=55,"46-55",Table1[[#This Row],[Age]]<=65,"56-65") -> 36-45
A14: EMP10013 | B14: 52 | C14: Male | D14: Finance | E14: Finance Manager | F14: Master's | G14: Technical Degree | H14: 3 | I14: 9455 | J14: 36 | K14: Yes | L14: 2 | M14: 3 | N14: 3 | O14: 0 | P14: 0 | Q14: 0 | R14: 0 | S14: 21 | T14: 2 | U14: 3 | V14: Travel_Rarely | W14: 15 | X14: Divorced | Y14: 4 | Z14: No | AA14: 44571 | AC14: Mumbai | AD14: Maharashtra | AE14: =COUNTBLANK(A14:AE14) -> 0 | AF14: =PROPER(UPPER(TRIM(Table1[[#This Row],[City]]))) -> Mumbai | AG14: =IF(ISBLANK(I14),AVERAGE($I$2:$I$3001),I14) -> 9455 | AH14: =_xlfn.IFS(Table1[[#This Row],[Age]]<=25,"18-25",Table1[[#This Row],[Age]]<=35,"26-35",Table1[[#This Row],[Age]]<=45,"36-45",Table1[[#This Row],[Age]]<=55,"46-55",Table1[[#This Row],[Age]]<=65,"56-65") -> 46-55
A15: EMP10014 | B15: 37 | C15: Female | D15: IT | E15: Developer | F15: Bachelor's | G15: Medical | H15: 2 | I15: 7104 | J15: 119 | K15: Yes | L15: 1 | M15: 3 | N15: 3 | O15: 9 | P15: 4 | Q15: 0 | R15: 0 | S15: 13 | T15: 6 | U15: 3 | V15: Travel_Rarely | W15: 8 | X15: Single | Y15: 2 | Z15: No | AA15: 44370 | AC15: Ahmedabad | AD15: Gujarat | AE15: =COUNTBLANK(A15:AE15) -> 0 | AF15: =PROPER(UPPER(TRIM(Table1[[#This Row],[City]]))) -> Ahmedabad | AG15: =IF(ISBLANK(I15),AVERAGE($I$2:$I$3001),I15) -> 7104 | AH15: =_xlfn.IFS(Table1[[#This Row],[Age]]<=25,"18-25",Table1[[#This Row],[Age]]<=35,"26-35",Table1[[#This Row],[Age]]<=45,"36-45",Table1[[#This Row],[Age]]<=55,"46-55",Table1[[#This Row],[Age]]<=65,"56-65") -> 36-45
A16: EMP10015 | B16: 55 | C16: Male | D16: Research & Development | E16: Laboratory Technician | F16: Doctorate | G16: Marketing | H16: 2 | I16: 6870 | J16: 47 | K16: No | L16: 2 | M16: 4 | N16: 1 | O16: 6 | P16: 0 | Q16: 0 | R16: 2 | S16: 23 | T16: 2 | U16: 4 | V16: Travel_Rarely | W16: 2 | X16: Married | Y16: 2 | Z16: No | AA16: 45500 | AC16: Ahmedabad | AD16: Gujarat | AE16: =COUNTBLANK(A16:AE16) -> 0 | AF16: =PROPER(UPPER(TRIM(Table1[[#This Row],[City]]))) -> Ahmedabad | AG16: =IF(ISBLANK(I16),AVERAGE($I$2:$I$3001),I16) -> 6870 | AH16: =_xlfn.IFS(Table1[[#This Row],[Age]]<=25,"18-25",Table1[[#This Row],[Age]]<=35,"26-35",Table1[[#This Row],[Age]]<=45,"36-45",Table1[[#This Row],[Age]]<=55,"46-55",Table1[[#This Row],[Age]]<=65,"56-65") -> 46-55
A17: EMP10016 | B17: 28 | C17: Male | D17: Research & Development | E17: Research Scientist | F17: Master's | G17: Other | H17: 4 | I17: 8761 | J17: 34 | K17: No | L17: 4 | M17: 4 | N17: 1 | O17: 0 | P17: 0 | Q17: 0 | R17: 0 | S17: 0 | T17: 2 | U17: 3 | V17: Travel_Frequently | W17: 16 | X17: Married | Y17: 4 | Z17: No | AA17: 44401 | AC17: Pune | AD17: Maharashtra | AE17: =COUNTBLANK(A17:AE17) -> 0 | AF17: =PROPER(UPPER(TRIM(Table1[[#This Row],[City]]))) -> Pune | AG17: =IF(ISBLANK(I17),AVERAGE($I$2:$I$3001),I17) -> 8761 | AH17: =_xlfn.IFS(Table1[[#This Row],[Age]]<=25,"18-25",Table1[[#This Row],[Age]]<=35,"26-35",Table1[[#This Row],[Age]]<=45,"36-45",Table1[[#This Row],[Age]]<=55,"46-55",Table1[[#This Row],[Age]]<=65,"56-65") -> 26-35
A18: EMP10017 | B18: 36 | C18: Male | D18: Human Resources | E18: Human Resources | F18: Master's | G18: Life Sciences | H18: 2 | I18: 8347 | J18: 108 | K18: Yes | L18: 4 | M18: 3 | N18: 1 | O18: 5 | P18: 0 | Q18: 4 | R18: 2 | S18: 15 | T18: 1 | U18: 3 | V18: Travel_Rarely | W18: 24 | X18: Married | Y18: 1 | Z18: Yes | AA18: 43261 | AB18: 43651 | AC18: Pune | AD18: Maharashtra | AE18: =COUNTBLANK(A18:AE18) -> 0 | AF18: =PROPER(UPPER(TRIM(Table1[[#This Row],[City]]))) -> Pune | AG18: =IF(ISBLANK(I18),AVERAGE($I$2:$I$3001),I18) -> 8347 | AH18: =_xlfn.IFS(Table1[[#This Row],[Age]]<=25,"18-25",Table1[[#This Row],[Age]]<=35,"26-35",Table1[[#This Row],[Age]]<=45,"36-45",Table1[[#This Row],[Age]]<=55,"46-55",Table1[[#This Row],[Age]]<=65,"56-65") -> 36-45
A19: EMP10018 | B19: 51 | C19: Female | D19: Sales | E19: Sales Executive | F19: Bachelor's | G19: Human Resources | H19: 1 | I19: 6666 | J19: 97 | K19: No | L19: 4 | M19: 3 | N19: 2 | O19: 6 | P19: 5 | Q19: 5 | R19: 4 | S19: 14 | T19: 2 | U19: 3 | V19: Travel_Rarely | W19: 6 | X19: Married | Y19: 3 | Z19: No | AA19: 45062 | AC19: Ahmedabad | AD19: Gujarat | AE19: =COUNTBLANK(A19:AE19) -> 0 | AF19: =PROPER(UPPER(TRIM(Table1[[#This Row],[City]]))) -> Ahmedabad | AG19: =IF(ISBLANK(I19),AVERAGE($I$2:$I$3001),I19) -> 6666 | AH19: =_xlfn.IFS(Table1[[#This Row],[Age]]<=25,"18-25",Table1[[#This Row],[Age]]<=35,"26-35",Table1[[#This Row],[Age]]<=45,"36-45",Table1[[#This Row],[Age]]<=55,"46-55",Table1[[#This Row],[Age]]<=65,"56-65") -> 46-55
A20: EMP10019 | B20: 25 | C20: Female | D20: IT | E20: IT Manager | F20: Master's | G20: Life Sciences | H20: 2 | I20: 4448 | J20: 81 | K20: No | L20: 3 | M20: 1 | N20: 3 | O20: 2 | P20: 2 | Q20: 2 | R20: 2 | S20: 2 | T20: 1 | U20: 3 | V20: Travel_Rarely | W20: 28 | X20: Married | Y20: 3 | Z20: No | AA20: 45032 | AC20: Pune | AD20: Maharashtra | AE20: =COUNTBLANK(A20:AE20) -> 0 | AF20: =PROPER(UPPER(TRIM(Table1[[#This Row],[City]]))) -> Pune | AG20: =IF(ISBLANK(I20),AVERAGE($I$2:$I$3001),I20) -> 4448 | AH20: =_xlfn.IFS(Table1[[#This Row],[Age]]<=25,"18-25",Table1[[#This Row],[Age]]<=35,"26-35",Table1[[#This Row],[Age]]<=45,"36-45",Table1[[#This Row],[Age]]<=55,"46-55",Table1[[#This Row],[Age]]<=65,"56-65") -> 18-25
A21: EMP10020 | B21: 33 | C21: Female | D21: Finance | E21: Finance Manager | F21: Master's | G21: Marketing | H21: 2 | I21: 6541 | J21: 35 | K21: No | L21: 4 | M21: 1 | N21: 1 | O21: 5 | P21: 5 | Q21: 4 | R21: 4 | S21: 5 | T21: 4 | U21: 3 | V21: Travel_Frequently | W21: 23 | X21: Married | Y21: 4 | Z21: No | AA21: 45381 | AC21: Ahmedabad | AD21: Gujarat | AE21: =COUNTBLANK(A21:AE21) -> 0 | AF21: =PROPER(UPPER(TRIM(Table1[[#This Row],[City]]))) -> Ahmedabad | AG21: =IF(ISBLANK(I21),AVERAGE($I$2:$I$3001),I21) -> 6541 | AH21: =_xlfn.IFS(Table1[[#This Row],[Age]]<=25,"18-25",Table1[[#This Row],[Age]]<=35,"26-35",Table1[[#This Row],[Age]]<=45,"36-45",Table1[[#This Row],[Age]]<=55,"46-55",Table1[[#This Row],[Age]]<=65,"56-65") -> 26-35
A22: EMP10021 | B22: 51 | C22: Female | D22: IT | E22: IT Support | F22: Bachelor's | G22: Human Resources | H22: 3 | I22: 10642 | J22: 55 | K22: No | L22: 4 | M22: 3 | N22: 4 | O22: 1 | P22: 1 | Q22: 1 | R22: 1 | S22: 18 | T22: 5 | U22: 3 | V22: Travel_Frequently | W22: 20 | X22: Married | Y22: 2 | Z22: No | AA22: 44656 | AC22: Chennai | AD22: Tamil Nadu | AE22: =COUNTBLANK(A22:AE22) -> 0 | AF22: =PROPER(UPPER(TRIM(Table1[[#This Row],[City]]))) -> Chennai | AG22: =IF(ISBLANK(I22),AVERAGE($I$2:$I$3001),I22) -> 10642 | AH22: =_xlfn.IFS(Table1[[#This Row],[Age]]<=25,"18-25",Table1[[#This Row],[Age]]<=35,"26-35",Table1[[#This Row],[Age]]<=45,"36-45",Table1[[#This Row],[Age]]<=55,"46-55",Table1[[#This Row],[Age]]<=65,"56-65") -> 46-55
A23: EMP10022 | B23: 44 | C23: Female | D23: Research & Development | E23: Research Scientist | F23: Doctorate | G23: Other | H23: 3 | I23: 9213 | J23: 85 | K23: No | L23: 1 | M23: 2 | N23: 3 | O23: 5 | P23: 5 | Q23: 3 | R23: 5 | S23: 18 | T23: 5 | U23: 3 | V23: Travel_Rarely | W23: 10 | X23: Married | Y23: 4 | Z23: No | AA23: 45602 | AC23: Coimbatore | AD23: Tamil Nadu | AE23: =COUNTBLANK(A23:AE23) -> 0 | AF23: =PROPER(UPPER(TRIM(Table1[[#This Row],[City]]))) -> Coimbatore | AG23: =IF(ISBLANK(I23),AVERAGE($I$2:$I$3001),I23) -> 9213 | AH23: =_xlfn.IFS(Table1[[#This Row],[Age]]<=25,"18-25",Table1[[#This Row],[Age]]<=35,"26-35",Table1[[#This Row],[Age]]<=45,"36-45",Table1[[#This Row],[Age]]<=55,"46-55",Table1[[#This Row],[Age]]<=65,"56-65") -> 36-45
A24: EMP10023 | B24: 52 | C24: Male | D24: Operations | E24: Operations Manager | F24: Master's | G24: Medical | H24: 2 | I24: 9226 | J24: 91 | K24: No | L24: 2 | M24: 2 | N24: 3 | O24: 8 | P24: 3 | Q24: 0 | R24: 0 | S24: 27 | T24: 5 | U24: 3 | V24: Travel_Rarely | W24: 22 | X24: Divorced | Y24: 3 | Z24: No | AA24: 44476 | AC24: Mumbai | AD24: Maharashtra | AE24: =COUNTBLANK(A24:AE24) -> 0 | AF24: =PROPER(UPPER(TRIM(Table1[[#This Row],[City]]))) -> Mumbai | AG24: =IF(ISBLANK(I24),AVERAGE($I$2:$I$3001),I24) -> 9226 | AH24: =_xlfn.IFS(Table1[[#This Row],[Age]]<=25,"18-25",Table1[[#This Row],[Age]]<=35,"26-35",Table1[[#This Row],[Age]]<=45,"36-45",Table1[[#This Row],[Age]]<=55,"46-55",Table1[[#This Row],[Age]]<=65,"56-65") -> 46-55
A25: EMP10024 | B25: 41 | C25: Female | D25: Operations | E25: Logistics Specialist | F25: Bachelor's | G25: Life Sciences | H25: 2 | I25: 8445 | J25: 93 | K25: Yes | L25: 3 | M25: 3 | N25: 4 | O25: 4 | P25: 3 | Q25: 2 | R25: 0 | S25: 9 | T25: 4 | U25: 3 | V25: Travel_Rarely | W25: 30 | X25: Single | Y25: 2 | Z25: No | AA25: 44826 | AC25: Ahmedabad | AD25: Gujarat | AE25: =COUNTBLANK(A25:AE25) -> 0 | AF25: =PROPER(UPPER(TRIM(Table1[[#This Row],[City]]))) -> Ahmedabad | AG25: =IF(ISBLANK(I25),AVERAGE($I$2:$I$3001),I25) -> 8445 | AH25: =_xlfn.IFS(Table1[[#This Row],[Age]]<=25,"18-25",Table1[[#This Row],[Age]]<=35,"26-35",Table1[[#This Row],[Age]]<=45,"36-45",Table1[[#This Row],[Age]]<=55,"46-55",Table1[[#This Row],[Age]]<=65,"56-65") -> 36-45
A26: EMP10025 | B26: 55 | C26: Female | D26: IT | E26: Developer | F26: Master's | G26: Human Resources | H26: 2 | I26: 7049 | J26: 48 | K26: No | L26: 2 | M26: 1 | N26: 3 | O26: 8 | P26: 4 | Q26: 1 | R26: 4 | S26: 22 | T26: 4 | U26: 3 | V26: Travel_Rarely | W26: 9 | X26: Single | Y26: 3 | Z26: No | AA26: 45727 | AC26: Chennai | AD26: Tamil Nadu | AE26: =COUNTBLANK(A26:AE26) -> 0 | AF26: =PROPER(UPPER(TRIM(Table1[[#This Row],[City]]))) -> Chennai | AG26: =IF(ISBLANK(I26),AVERAGE($I$2:$I$3001),I26) -> 7049 | AH26: =_xlfn.IFS(Table1[[#This Row],[Age]]<=25,"18-25",Table1[[#This Row],[Age]]<=35,"26-35",Table1[[#This Row],[Age]]<=45,"36-45",Table1[[#This Row],[Age]]<=55,"46-55",Table1[[#This Row],[Age]]<=65,"56-65") -> 46-55
A27: EMP10026 | B27: 56 | C27: Female | D27: Sales | E27: Manager | F27: Bachelor's | G27: Other | H27: 1 | I27: 6396 | J27: 90 | K27: No | L27: 4 | M27: 2 | N27: 1 | O27: 5 | P27: 5 | Q27: 2 | R27: 5 | S27: 18 | T27: 2 | U27: 3 | V27: Travel_Rarely | W27: 19 | X27: Married | Y27: 2 | Z27: No | AA27: 44523 | AC27: Kolkata | AD27: West Bengal | AE27: =COUNTBLANK(A27:AE27) -> 0 | AF27: =PROPER(UPPER(TRIM(Table1[[#This Row],[City]]))) -> Kolkata | AG27: =IF(ISBLANK(I27),AVERAGE($I$2:$I$3001),I27) -> 6396 | AH27: =_xlfn.IFS(Table1[[#This Row],[Age]]<=25,"18-25",Table1[[#This Row],[Age]]<=35,"26-35",Table1[[#This Row],[Age]]<=45,"36-45",Table1[[#This Row],[Age]]<=55,"46-55",Table1[[#This Row],[Age]]<=65,"56-65") -> 56-65
A28: EMP10027 | B28: 59 | C28: Male | D28: Research & Development | E28: Laboratory Technician | F28: Master's | G28: Technical Degree | H28: 3 | I28: 9887 | J28: 35 | K28: No | L28: 4 | M28: 1 | N28: 4 | O28: 7 | P28: 4 | Q28: 2 | R28: 0 | S28: 24 | T28: 6 | U28: 3 | V28: Travel_Frequently | W28: 13 | X28: Single | Y28: 3 | Z28: No | AA28: 44386 | AC28: kolkata | AD28: West Bengal | AE28: =COUNTBLANK(A28:AE28) -> 0 | AF28: =PROPER(UPPER(TRIM(Table1[[#This Row],[City]]))) -> Kolkata | AG28: =IF(ISBLANK(I28),AVERAGE($I$2:$I$3001),I28) -> 9887 | AH28: =_xlfn.IFS(Table1[[#This Row],[Age]]<=25,"18-25",Table1[[#This Row],[Age]]<=35,"26-35",Table1[[#This Row],[Age]]<=45,"36-45",Table1[[#This Row],[Age]]<=55,"46-55",Table1[[#This Row],[Age]]<=65,"56-65") -> 56-65
A29: EMP10028 | B29: 25 | C29: Male | D29: Sales | E29: Manager | F29: Master's | G29: Life Sciences | H29: 1 | I29: 3570 | J29: 50 | K29: No | L29: 3 | M29: 4 | N29: 4 | O29: 5 | P29: 0 | Q29: 0 | R29: 2 | S29: 5 | T29: 6 | U29: 4 | V29: Travel_Frequently | W29: 19 | X29: Divorced | Y29: 2 | Z29: No | AA29: 42067 | AC29: Mumbai | AD29: Maharashtra | AE29: =COUNTBLANK(A29:AE29) -> 0 | AF29: =PROPER(UPPER(TRIM(Table1[[#This Row],[City]]))) -> Mumbai | AG29: =IF(ISBLANK(I29),AVERAGE($I$2:$I$3001),I29) -> 3570 | AH29: =_xlfn.IFS(Table1[[#This Row],[Age]]<=25,"18-25",Table1[[#This Row],[Age]]<=35,"26-35",Table1[[#This Row],[Age]]<=45,"36-45",Table1[[#This Row],[Age]]<=55,"46-55",Table1[[#This Row],[Age]]<=65,"56-65") -> 18-25
A30: EMP10029 | B30: 44 | C30: Female | D30: Sales | E30: Sales Representative | F30: High School | G30: Technical Degree | H30: 3 | I30: 8156 | J30: 26 | K30: No | L30: 1 | M30: 3 | N30: 1 | O30: 4 | P30: 1 | Q30: 0 | R30: 4 | S30: 20 | T30: 0 | U30: 3 | V30: Travel_Rarely | W30: 8 | X30: Single | Y30: 2 | Z30: No | AA30: 42932 | AC30: Coimbatore | AD30: Tamil Nadu | AE30: =COUNTBLANK(A30:AE30) -> 0 | AF30: =PROPER(UPPER(TRIM(Table1[[#This Row],[City]]))) -> Coimbatore | AG30: =IF(ISBLANK(I30),AVERAGE($I$2:$I$3001),I30) -> 8156 | AH30: =_xlfn.IFS(Table1[[#This Row],[Age]]<=25,"18-25",Table1[[#This Row],[Age]]<=35,"26-35",Table1[[#This Row],[Age]]<=45,"36-45",Table1[[#This Row],[Age]]<=55,"46-55",Table1[[#This Row],[Age]]<=65,"56-65") -> 36-45
... A37: EMP10036 | B37: 32 | C37: Female | D37: Sales | E37: Sales Executive | F37: Bachelor's | G37: Other | H37: 2 | I37: 6765 | J37: 67 | K37: Yes | L37: 2 | M37: 4 | N37: 3 | O37: 9 | P37: 0 | Q37: 0 | R37: 0 | S37: 9 | T37: 6 | U37: 3 | V37: Travel_Rarely | W37: 26 | X37: Married | Y37: 4 | Z37: No | AA37: 45594 | AC37: Kolkata | AD37: West Bengal | AE37: =COUNTBLANK(A37:AE37) -> 0 | AF37: =PROPER(UPPER(TRIM(Table1[[#This Row],[City]]))) -> Kolkata | AG37: =IF(ISBLANK(I37),AVERAGE($I$2:$I$3001),I37) -> 6765 | AH37: =_xlfn.IFS(Table1[[#This Row],[Age]]<=25,"18-25",Table1[[#This Row],[Age]]<=35,"26-35",Table1[[#This Row],[Age]]<=45,"36-45",Table1[[#This Row],[Age]]<=55,"46-55",Table1[[#This Row],[Age]]<=65,"56-65") -> 26-35
A38: EMP10037 | B38: 45 | C38: Female | D38: Sales | E38: Sales Representative | F38: Master's | G38: Technical Degree | H38: 3 | I38: 10063 | J38: 59 | K38: Yes | L38: 1 | M38: 3 | N38: 4 | O38: 0 | P38: 0 | Q38: 0 | R38: 0 | S38: 13 | T38: 4 | U38: 4 | V38: Travel_Rarely | W38: 28 | X38: Married | Y38: 1 | Z38: Yes | AA38: 43757 | AB38: 45601 | AC38: Kochi | AD38: Kerala | AE38: =COUNTBLANK(A38:AE38) -> 0 | AF38: =PROPER(UPPER(TRIM(Table1[[#This Row],[City]]))) -> Kochi | AG38: =IF(ISBLANK(I38),AVERAGE($I$2:$I$3001),I38) -> 10063 | AH38: =_xlfn.IFS(Table1[[#This Row],[Age]]<=25,"18-25",Table1[[#This Row],[Age]]<=35,"26-35",Table1[[#This Row],[Age]]<=45,"36-45",Table1[[#This Row],[Age]]<=55,"46-55",Table1[[#This Row],[Age]]<=65,"56-65") -> 36-45
A39: EMP10038 | B39: 51 | C39: Male | D39: Research & Development | E39: Research Scientist | F39: Bachelor's | G39: Technical Degree | H39: 4 | I39: 11516 | J39: 57 | K39: No | L39: 1 | M39: 3 | N39: 2 | O39: 5 | P39: 1 | Q39: 1 | R39: 3 | S39: 21 | T39: 6 | U39: 3 | V39: Travel_Rarely | W39: 30 | X39: Married | Y39: 4 | Z39: No | AA39: 44922 | AC39: Chennai | AD39: Tamil Nadu | AE39: =COUNTBLANK(A39:AE39) -> 0 | AF39: =PROPER(UPPER(TRIM(Table1[[#This Row],[City]]))) -> Chennai | AG39: =IF(ISBLANK(I39),AVERAGE($I$2:$I$3001),I39) -> 11516 | AH39: =_xlfn.IFS(Table1[[#This Row],[Age]]<=25,"18-25",Table1[[#This Row],[Age]]<=35,"26-35",Table1[[#This Row],[Age]]<=45,"36-45",Table1[[#This Row],[Age]]<=55,"46-55",Table1[[#This Row],[Age]]<=65,"56-65") -> 46-55
A40: EMP10039 | B40: 60 | C40: Male | D40: Research & Development | E40: Laboratory Technician | F40: Bachelor's | G40: Other | H40: 2 | I40: 8148 | J40: 54 | K40: No | L40: 2 | M40: 3 | N40: 4 | O40: 10 | P40: 1 | Q40: 0 | R40: 1 | S40: 24 | T40: 4 | U40: 3 | V40: Travel_Rarely | W40: 29 | X40: Married | Y40: 3 | Z40: Yes | AA40: 42244 | AB40: 44228 | AC40: Hyderabad | AD40: Telangana | AE40: =COUNTBLANK(A40:AE40) -> 0 | AF40: =PROPER(UPPER(TRIM(Table1[[#This Row],[City]]))) -> Hyderabad | AG40: =IF(ISBLANK(I40),AVERAGE($I$2:$I$3001),I40) -> 8148 | AH40: =_xlfn.IFS(Table1[[#This Row],[Age]]<=25,"18-25",Table1[[#This Row],[Age]]<=35,"26-35",Table1[[#This Row],[Age]]<=45,"36-45",Table1[[#This Row],[Age]]<=55,"46-55",Table1[[#This Row],[Age]]<=65,"56-65") -> 56-65
A41: EMP10040 | B41: 30 | C41: Male | D41: Finance | E41: Finance Analyst | F41: High School | G41: Medical | H41: 4 | I41: 12202 | J41: 110 | K41: No | L41: 3 | M41: 3 | N41: 2 | O41: 3 | P41: 2 | Q41: 3 | R41: 2 | S41: 10 | T41: 3 | U41: 3 | V41: Travel_Rarely | W41: 7 | X41: Divorced | Y41: 4 | Z41: No | AA41: 44549 | AC41: Pune | AD41: Maharashtra | AE41: =COUNTBLANK(A41:AE41) -> 0 | AF41: =PROPER(UPPER(TRIM(Table1[[#This Row],[City]]))) -> Pune | AG41: =IF(ISBLANK(I41),AVERAGE($I$2:$I$3001),I41) -> 12202 | AH41: =_xlfn.IFS(Table1[[#This Row],[Age]]<=25,"18-25",Table1[[#This Row],[Age]]<=35,"26-35",Table1[[#This Row],[Age]]<=45,"36-45",Table1[[#This Row],[Age]]<=55,"46-55",Table1[[#This Row],[Age]]<=65,"56-65") -> 26-35
A42: EMP10041 | B42: 50 | C42: Male | D42: Research & Development | E42: Laboratory Technician | F42: Bachelor's | G42: Other | H42: 1 | I42: 4098 | J42: 32 | K42: No | L42: 3 | M42: 1 | N42: 4 | O42: 7 | P42: 6 | Q42: 2 | R42: 7 | S42: 25 | T42: 1 | U42: 3 | V42: Travel_Rarely | W42: 27 | X42: Married | Y42: 3 | Z42: No | AA42: 45544 | AC42: Bengaluru | AD42: Karnataka | AE42: =COUNTBLANK(A42:AE42) -> 0 | AF42: =PROPER(UPPER(TRIM(Table1[[#This Row],[City]]))) -> Bengaluru | AG42: =IF(ISBLANK(I42),AVERAGE($I$2:$I$3001),I42) -> 4098 | AH42: =_xlfn.IFS(Table1[[#This Row],[Age]]<=25,"18-25",Table1[[#This Row],[Age]]<=35,"26-35",Table1[[#This Row],[Age]]<=45,"36-45",Table1[[#This Row],[Age]]<=55,"46-55",Table1[[#This Row],[Age]]<=65,"56-65") -> 46-55
A43: EMP10042 | B43: 24 | C43: Male | D43: IT | E43: Developer | F43: Bachelor's | G43: Medical | H43: 5 | I43: 10279 | J43: 102 | K43: Yes | L43: 2 | M43: 2 | N43: 1 | O43: 8 | P43: 4 | Q43: 0 | R43: 6 | S43: 8 | T43: 6 | U43: 3 | V43: Travel_Rarely | W43: 30 | X43: Married | Y43: 1 | Z43: No | AA43: 42504 | AC43: Kolkata | AD43: West Bengal | AE43: =COUNTBLANK(A43:AE43) -> 0 | AF43: =PROPER(UPPER(TRIM(Table1[[#This Row],[City]]))) -> Kolkata | AG43: =IF(ISBLANK(I43),AVERAGE($I$2:$I$3001),I43) -> 10279 | AH43: =_xlfn.IFS(Table1[[#This Row],[Age]]<=25,"18-25",Table1[[#This Row],[Age]]<=35,"26-35",Table1[[#This Row],[Age]]<=45,"36-45",Table1[[#This Row],[Age]]<=55,"46-55",Table1[[#This Row],[Age]]<=65,"56-65") -> 18-25
A44: EMP10043 | B44: 42 | C44: Female | D44: Finance | E44: Finance Analyst | F44: Bachelor's | G44: Marketing | H44: 1 | I44: 6099 | J44: 49 | K44: No | L44: 3 | M44: 4 | N44: 4 | O44: 0 | P44: 0 | Q44: 0 | R44: 0 | S44: 16 | T44: 1 | U44: 3 | V44: Travel_Rarely | W44: 17 | X44: Married | Y44: 2 | Z44: No | AA44: 42722 | AC44: Hyderabad | AD44: Telangana | AE44: =COUNTBLANK(A44:AE44) -> 0 | AF44: =PROPER(UPPER(TRIM(Table1[[#This Row],[City]]))) -> Hyderabad | AG44: =IF(ISBLANK(I44),AVERAGE($I$2:$I$3001),I44) -> 6099 | AH44: =_xlfn.IFS(Table1[[#This Row],[Age]]<=25,"18-25",Table1[[#This Row],[Age]]<=35,"26-35",Table1[[#This Row],[Age]]<=45,"36-45",Table1[[#This Row],[Age]]<=55,"46-55",Table1[[#This Row],[Age]]<=65,"56-65") -> 36-45
A45: EMP10044 | B45: 37 | C45: Female | D45: Research & Development | E45: Research Director | F45: Master's | G45: Marketing | H45: 2 | I45: 7042 | J45: 33 | K45: No | L45: 1 | M45: 4 | N45: 1 | O45: 6 | P45: 1 | Q45: 2 | R45: 4 | S45: 17 | T45: 1 | U45: 3 | V45: Travel_Rarely | W45: 19 | X45: Married | Y45: 4 | Z45: Yes | AA45: 44637 | AB45: 46238 | AC45: Kochi | AD45: Kerala | AE45: =COUNTBLANK(A45:AE45) -> 0 | AF45: =PROPER(UPPER(TRIM(Table1[[#This Row],[City]]))) -> Kochi | AG45: =IF(ISBLANK(I45),AVERAGE($I$2:$I$3001),I45) -> 7042 | AH45: =_xlfn.IFS(Table1[[#This Row],[Age]]<=25,"18-25",Table1[[#This Row],[Age]]<=35,"26-35",Table1[[#This Row],[Age]]<=45,"36-45",Table1[[#This Row],[Age]]<=55,"46-55",Table1[[#This Row],[Age]]<=65,"56-65") -> 36-45
A46: EMP10045 | B46: 59 | C46: Male | D46: IT | E46: Developer | F46: Bachelor's | G46: Technical Degree | H46: 1 | I46: 5397 | J46: 107 | K46: Yes | L46: 3 | M46: 3 | N46: 4 | O46: 10 | P46: 6 | Q46: 1 | R46: 0 | S46: 23 | T46: 5 | U46: 3 | V46: Non-Travel | W46: 27 | X46: Single | Y46: 1 | Z46: Yes | AA46: 44496 | AB46: 45089 | AC46: Kolkata | AD46: West Bengal | AE46: =COUNTBLANK(A46:AE46) -> 0 | AF46: =PROPER(UPPER(TRIM(Table1[[#This Row],[City]]))) -> Kolkata | AG46: =IF(ISBLANK(I46),AVERAGE($I$2:$I$3001),I46) -> 5397 | AH46: =_xlfn.IFS(Table1[[#This Row],[Age]]<=25,"18-25",Table1[[#This Row],[Age]]<=35,"26-35",Table1[[#This Row],[Age]]<=45,"36-45",Table1[[#This Row],[Age]]<=55,"46-55",Table1[[#This Row],[Age]]<=65,"56-65") -> 56-65
...

Sheet Departments
A1: DepartmentID | B1: Department
A2: D01 | B2: Sales
A3: D02 | B3: Research & Development
A4: D03 | B4: Human Resources
A5: D04 | B5: Finance
A6: D05 | B6: IT
A7: D06 | B7: Operations

Sheet JobRoles
A1: JobRoleID | B1: JobRole
A2: JR001 | B2: Developer
A3: JR002 | B3: Finance Analyst
A4: JR003 | B4: Finance Manager
A5: JR004 | B5: Human Resources
A6: JR005 | B6: IT Manager
A7: JR006 | B7: IT Support
A8: JR007 | B8: Laboratory Technician
A9: JR008 | B9: Logistics Specialist
A10: JR009 | B10: Manager
A11: JR010 | B11: Operations Coordinator
A12: JR011 | B12: Operations Manager
... A16: JR015 | B16: Sales Representative

Sheet SalaryHistory
A1: EmployeeID | B1: HireDate | C1: MonthlyIncome | D1: JobLevel | E1: SalaryEffectiveDate | F1: SalaryBand | G1: MonthlyIncome_Clean | H1: Salary Band clear | I1: Attrition
A2: EMP11779 | B2: 44491 | C2: 11996 | D2: 4 | E2: 44491 | F2: Upper-Mid | G2: =IFERROR(VLOOKUP(Table4[[#This Row],[EmployeeID]],Employees!$A:$AG,33,FALSE),"") -> 11996 | H2: =_xlfn.IFS( Table4[[#This Row],[MonthlyIncome_Clean]]<=2980,"Lower", Table4[[#This Row],[MonthlyIncome_Clean]]<=5000,"Lower Mid", Table4[[#This Row],[MonthlyIncome_Clean]]<=8000,"Mid", Table4[[#This Row],[MonthlyIncome_Clean]]<=11996,"Upper Mid", Table4[[#This Row],[MonthlyIncome_Clean]]<=16000,"High" ) -> Upper Mid | I2: =IFERROR(VLOOKUP(A2,Table1[#All],26,FALSE),"") -> No
A3: EMP11649 | B3: 44683 | C3: 8000 | D3: 2 | E3: 44683 | F3: Mid | G3: =IFERROR(VLOOKUP(Table4[[#This Row],[EmployeeID]],Employees!$A:$AG,33,FALSE),"") -> 8000 | H3: =_xlfn.IFS( Table4[[#This Row],[MonthlyIncome_Clean]]<=2980,"Lower", Table4[[#This Row],[MonthlyIncome_Clean]]<=5000,"Lower Mid", Table4[[#This Row],[MonthlyIncome_Clean]]<=8000,"Mid", Table4[[#This Row],[MonthlyIncome_Clean]]<=11996,"Upper Mid", Table4[[#This Row],[MonthlyIncome_Clean]]<=16000,"High" ) -> Mid | I3: =IFERROR(VLOOKUP(A3,Table1[#All],26,FALSE),"") -> No
A4: EMP12628 | B4: 44311 | C4: 7997 | D4: 2 | E4: 44311 | F4: Mid | G4: =IFERROR(VLOOKUP(Table4[[#This Row],[EmployeeID]],Employees!$A:$AG,33,FALSE),"") -> 7997 | H4: =_xlfn.IFS( Table4[[#This Row],[MonthlyIncome_Clean]]<=2980,"Lower", Table4[[#This Row],[MonthlyIncome_Clean]]<=5000,"Lower Mid", Table4[[#This Row],[MonthlyIncome_Clean]]<=8000,"Mid", Table4[[#This Row],[MonthlyIncome_Clean]]<=11996,"Upper Mid", Table4[[#This Row],[MonthlyIncome_Clean]]<=16000,"High" ) -> Mid | I4: =IFERROR(VLOOKUP(A4,Table1[#All],26,FALSE),"") -> No
A5: EMP11942 | B5: 46017 | C5: 11996 | D5: 4 | E5: 46017 | F5: Upper-Mid | G5: =IFERROR(VLOOKUP(Table4[[#This Row],[EmployeeID]],Employees!$A:$AG,33,FALSE),"") -> 11996 | H5: =_xlfn.IFS( Table4[[#This Row],[MonthlyIncome_Clean]]<=2980,"Lower", Table4[[#This Row],[MonthlyIncome_Clean]]<=5000,"Lower Mid", Table4[[#This Row],[MonthlyIncome_Clean]]<=8000,"Mid", Table4[[#This Row],[MonthlyIncome_Clean]]<=11996,"Upper Mid", Table4[[#This Row],[MonthlyIncome_Clean]]<=16000,"High" ) -> Upper Mid | I5: =IFERROR(VLOOKUP(A5,Table1[#All],26,FALSE),"") -> No
A6: EMP12843 | B6: 43511 | C6: 7995 | D6: 2 | E6: 43511 | F6: Mid | G6: =IFERROR(VLOOKUP(Table4[[#This Row],[EmployeeID]],Employees!$A:$AG,33,FALSE),"") -> 7995 | H6: =_xlfn.IFS( Table4[[#This Row],[MonthlyIncome_Clean]]<=2980,"Lower", Table4[[#This Row],[MonthlyIncome_Clean]]<=5000,"Lower Mid", Table4[[#This Row],[MonthlyIncome_Clean]]<=8000,"Mid", Table4[[#This Row],[MonthlyIncome_Clean]]<=11996,"Upper Mid", Table4[[#This Row],[MonthlyIncome_Clean]]<=16000,"High" ) -> Mid | I6: =IFERROR(VLOOKUP(A6,Table1[#All],26,FALSE),"") -> No
A7: EMP10626 | B7: 45696 | C7: 11994 | D7: 4 | E7: 45696 | F7: Upper-Mid | G7: =IFERROR(VLOOKUP(Table4[[#This Row],[EmployeeID]],Employees!$A:$AG,33,FALSE),"") -> 11994 | H7: =_xlfn.IFS( Table4[[#This Row],[MonthlyIncome_Clean]]<=2980,"Lower", Table4[[#This Row],[MonthlyIncome_Clean]]<=5000,"Lower Mid", Table4[[#This Row],[MonthlyIncome_Clean]]<=8000,"Mid", Table4[[#This Row],[MonthlyIncome_Clean]]<=11996,"Upper Mid", Table4[[#This Row],[MonthlyIncome_Clean]]<=16000,"High" ) -> Upper Mid | I7: =IFERROR(VLOOKUP(A7,Table1[#All],26,FALSE),"") -> No
A8: EMP11806 | B8: 43014 | C8: 7992 | D8: 3 | E8: 43014 | F8: Mid | G8: =IFERROR(VLOOKUP(Table4[[#This Row],[EmployeeID]],Employees!$A:$AG,33,FALSE),"") -> 7992 | H8: =_xlfn.IFS( Table4[[#This Row],[MonthlyIncome_Clean]]<=2980,"Lower", Table4[[#This Row],[MonthlyIncome_Clean]]<=5000,"Lower Mid", Table4[[#This Row],[MonthlyIncome_Clean]]<=8000,"Mid", Table4[[#This Row],[MonthlyIncome_Clean]]<=11996,"Upper Mid", Table4[[#This Row],[MonthlyIncome_Clean]]<=16000,"High" ) -> Mid | I8: =IFERROR(VLOOKUP(A8,Table1[#All],26,FALSE),"") -> No
A9: EMP11091 | B9: 43620 | C9: 11994 | D9: 4 | E9: 43620 | F9: Upper-Mid | G9: =IFERROR(VLOOKUP(Table4[[#This Row],[EmployeeID]],Employees!$A:$AG,33,FALSE),"") -> 11994 | H9: =_xlfn.IFS( Table4[[#This Row],[MonthlyIncome_Clean]]<=2980,"Lower", Table4[[#This Row],[MonthlyIncome_Clean]]<=5000,"Lower Mid", Table4[[#This Row],[MonthlyIncome_Clean]]<=8000,"Mid", Table4[[#This Row],[MonthlyIncome_Clean]]<=11996,"Upper Mid", Table4[[#This Row],[MonthlyIncome_Clean]]<=16000,"High" ) -> Upper Mid | I9: =IFERROR(VLOOKUP(A9,Table1[#All],26,FALSE),"") -> No
A10: EMP12749 | B10: 45275 | C10: 7991 | D10: 2 | E10: 45275 | F10: Mid | G10: =IFERROR(VLOOKUP(Table4[[#This Row],[EmployeeID]],Employees!$A:$AG,33,FALSE),"") -> 7991 | H10: =_xlfn.IFS( Table4[[#This Row],[MonthlyIncome_Clean]]<=2980,"Lower", Table4[[#This Row],[MonthlyIncome_Clean]]<=5000,"Lower Mid", Table4[[#This Row],[MonthlyIncome_Clean]]<=8000,"Mid", Table4[[#This Row],[MonthlyIncome_Clean]]<=11996,"Upper Mid", Table4[[#This Row],[MonthlyIncome_Clean]]<=16000,"High" ) -> Mid | I10: =IFERROR(VLOOKUP(A10,Table1[#All],26,FALSE),"") -> Yes
A11: EMP12527 | B11: 44639 | C11: 7989 | D11: 3 | E11: 44639 | F11: Mid | G11: =IFERROR(VLOOKUP(Table4[[#This Row],[EmployeeID]],Employees!$A:$AG,33,FALSE),"") -> 7989 | H11: =_xlfn.IFS( Table4[[#This Row],[MonthlyIncome_Clean]]<=2980,"Lower", Table4[[#This Row],[MonthlyIncome_Clean]]<=5000,"Lower Mid", Table4[[#This Row],[MonthlyIncome_Clean]]<=8000,"Mid", Table4[[#This Row],[MonthlyIncome_Clean]]<=11996,"Upper Mid", Table4[[#This Row],[MonthlyIncome_Clean]]<=16000,"High" ) -> Mid | I11: =IFERROR(VLOOKUP(A11,Table1[#All],26,FALSE),"") -> No
A12: EMP10128 | B12: 45346 | C12: 7988 | D12: 2 | E12: 45346 | F12: Mid | G12: =IFERROR(VLOOKUP(Table4[[#This Row],[EmployeeID]],Employees!$A:$AG,33,FALSE),"") -> 7988 | H12: =_xlfn.IFS( Table4[[#This Row],[MonthlyIncome_Clean]]<=2980,"Lower", Table4[[#This Row],[MonthlyIncome_Clean]]<=5000,"Lower Mid", Table4[[#This Row],[MonthlyIncome_Clean]]<=8000,"Mid", Table4[[#This Row],[MonthlyIncome_Clean]]<=11996,"Upper Mid", Table4[[#This Row],[MonthlyIncome_Clean]]<=16000,"High" ) -> Mid | I12: =IFERROR(VLOOKUP(A12,Table1[#All],26,FALSE),"") -> No
A13: EMP12413 | B13: 45060 | C13: 7984 | D13: 2 | E13: 45060 | F13: Mid | G13: =IFERROR(VLOOKUP(Table4[[#This Row],[EmployeeID]],Employees!$A:$AG,33,FALSE),"") -> 7984 | H13: =_xlfn.IFS( Table4[[#This Row],[MonthlyIncome_Clean]]<=2980,"Lower", Table4[[#This Row],[MonthlyIncome_Clean]]<=5000,"Lower Mid", Table4[[#This Row],[MonthlyIncome_Clean]]<=8000,"Mid", Table4[[#This Row],[MonthlyIncome_Clean]]<=11996,"Upper Mid", Table4[[#This Row],[MonthlyIncome_Clean]]<=16000,"High" ) -> Mid | I13: =IFERROR(VLOOKUP(A13,Table1[#All],26,FALSE),"") -> No
... A182: EMP11585 | B182: 42208 | C182: 7875 | D182: 2 | E182: 42208 | F182: Mid | G182: =IFERROR(VLOOKUP(Table4[[#This Row],[EmployeeID]],Employees!$A:$AG,33,FALSE),"") -> 7875 | H182: =_xlfn.IFS( Table4[[#This Row],[MonthlyIncome_Clean]]<=2980,"Lower", Table4[[#This Row],[MonthlyIncome_Clean]]<=5000,"Lower Mid", Table4[[#This Row],[MonthlyIncome_Clean]]<=8000,"Mid", Table4[[#This Row],[MonthlyIncome_Clean]]<=11996,"Upper Mid", Table4[[#This Row],[MonthlyIncome_Clean]]<=16000,"High" ) -> Mid | I182: =IFERROR(VLOOKUP(A182,Table1[#All],26,FALSE),"") -> No
A183: EMP10182 | B183: 43037 | D183: 1 | E183: 43037 | G183: =IFERROR(VLOOKUP(Table4[[#This Row],[EmployeeID]],Employees!$A:$AG,33,FALSE),"") -> 8287.5378 | H183: =_xlfn.IFS( Table4[[#This Row],[MonthlyIncome_Clean]]<=2980,"Lower", Table4[[#This Row],[MonthlyIncome_Clean]]<=5000,"Lower Mid", Table4[[#This Row],[MonthlyIncome_Clean]]<=8000,"Mid", Table4[[#This Row],[MonthlyIncome_Clean]]<=11996,"Upper Mid", Table4[[#This Row],[MonthlyIncome_Clean]]<=16000,"High" ) -> Upper Mid | I183: =IFERROR(VLOOKUP(A183,Table1[#All],26,FALSE),"") -> No
A184: EMP10652 | B184: 43270 | C184: 7874 | D184: 2 | E184: 43270 | F184: Mid | G184: =IFERROR(VLOOKUP(Table4[[#This Row],[EmployeeID]],Employees!$A:$AG,33,FALSE),"") -> 7874 | H184: =_xlfn.IFS( Table4[[#This Row],[MonthlyIncome_Clean]]<=2980,"Lower", Table4[[#This Row],[MonthlyIncome_Clean]]<=5000,"Lower Mid", Table4[[#This Row],[MonthlyIncome_Clean]]<=8000,"Mid", Table4[[#This Row],[MonthlyIncome_Clean]]<=11996,"Upper Mid", Table4[[#This Row],[MonthlyIncome_Clean]]<=16000,"High" ) -> Mid | I184: =IFERROR(VLOOKUP(A184,Table1[#All],26,FALSE),"") -> Yes
A185: EMP12854 | B185: 44840 | C185: 11476 | D185: 4 | E185: 44840 | F185: Upper-Mid | G185: =IFERROR(VLOOKUP(Table4[[#This Row],[EmployeeID]],Employees!$A:$AG,33,FALSE),"") -> 11476 | H185: =_xlfn.IFS( Table4[[#This Row],[MonthlyIncome_Clean]]<=2980,"Lower", Table4[[#This Row],[MonthlyIncome_Clean]]<=5000,"Lower Mid", Table4[[#This Row],[MonthlyIncome_Clean]]<=8000,"Mid", Table4[[#This Row],[MonthlyIncome_Clean]]<=11996,"Upper Mid", Table4[[#This Row],[MonthlyIncome_Clean]]<=16000,"High" ) -> Upper Mid | I185: =IFERROR(VLOOKUP(A185,Table1[#All],26,FALSE),"") -> No
A186: EMP11352 | B186: 42744 | C186: 7873 | D186: 3 | E186: 42744 | F186: Mid | G186: =IFERROR(VLOOKUP(Table4[[#This Row],[EmployeeID]],Employees!$A:$AG,33,FALSE),"") -> 7873 | H186: =_xlfn.IFS( Table4[[#This Row],[MonthlyIncome_Clean]]<=2980,"Lower", Table4[[#This Row],[MonthlyIncome_Clean]]<=5000,"Lower Mid", Table4[[#This Row],[MonthlyIncome_Clean]]<=8000,"Mid", Table4[[#This Row],[MonthlyIncome_Clean]]<=11996,"Upper Mid", Table4[[#This Row],[MonthlyIncome_Clean]]<=16000,"High" ) -> Mid | I186: =IFERROR(VLOOKUP(A186,Table1[#All],26,FALSE),"") -> Yes
A187: EMP10981 | B187: 42469 | C187: 7872 | D187: 3 | E187: 42469 | F187: Mid | G187: =IFERROR(VLOOKUP(Table4[[#This Row],[EmployeeID]],Employees!$A:$AG,33,FALSE),"") -> 7872 | H187: =_xlfn.IFS( Table4[[#This Row],[MonthlyIncome_Clean]]<=2980,"Lower", Table4[[#This Row],[MonthlyIncome_Clean]]<=5000,"Lower Mid", Table4[[#This Row],[MonthlyIncome_Clean]]<=8000,"Mid", Table4[[#This Row],[MonthlyIncome_Clean]]<=11996,"Upper Mid", Table4[[#This Row],[MonthlyIncome_Clean]]<=16000,"High" ) -> Mid | I187: =IFERROR(VLOOKUP(A187,Table1[#All],26,FALSE),"") -> No
A188: EMP11943 | B188: 44403 | C188: 7866 | D188: 3 | E188: 44403 | F188: Mid | G188: =IFERROR(VLOOKUP(Table4[[#This Row],[EmployeeID]],Employees!$A:$AG,33,FALSE),"") -> 7866 | H188: =_xlfn.IFS( Table4[[#This Row],[MonthlyIncome_Clean]]<=2980,"Lower", Table4[[#This Row],[MonthlyIncome_Clean]]<=5000,"Lower Mid", Table4[[#This Row],[MonthlyIncome_Clean]]<=8000,"Mid", Table4[[#This Row],[MonthlyIncome_Clean]]<=11996,"Upper Mid", Table4[[#This Row],[MonthlyIncome_Clean]]<=16000,"High" ) -> Mid | I188: =IFERROR(VLOOKUP(A188,Table1[#All],26,FALSE),"") -> No
A189: EMP11046 | B189: 44096 | C189: 7864 | D189: 2 | E189: 44096 | F189: Mid | G189: =IFERROR(VLOOKUP(Table4[[#This Row],[EmployeeID]],Employees!$A:$AG,33,FALSE),"") -> 7864 | H189: =_xlfn.IFS( Table4[[#This Row],[MonthlyIncome_Clean]]<=2980,"Lower", Table4[[#This Row],[MonthlyIncome_Clean]]<=5000,"Lower Mid", Table4[[#This Row],[MonthlyIncome_Clean]]<=8000,"Mid", Table4[[#This Row],[MonthlyIncome_Clean]]<=11996,"Upper Mid", Table4[[#This Row],[MonthlyIncome_Clean]]<=16000,"High" ) -> Mid | I189: =IFERROR(VLOOKUP(A189,Table1[#All],26,FALSE),"") -> No
A190: EMP12457 | B190: 43887 | C190: 7864 | D190: 3 | E190: 43887 | F190: Mid | G190: =IFERROR(VLOOKUP(Table4[[#This Row],[EmployeeID]],Employees!$A:$AG,33,FALSE),"") -> 7864 | H190: =_xlfn.IFS( Table4[[#This Row],[MonthlyIncome_Clean]]<=2980,"Lower", Table4[[#This Row],[MonthlyIncome_Clean]]<=5000,"Lower Mid", Table4[[#This Row],[MonthlyIncome_Clean]]<=8000,"Mid", Table4[[#This Row],[MonthlyIncome_Clean]]<=11996,"Upper Mid", Table4[[#This Row],[MonthlyIncome_Clean]]<=16000,"High" ) -> Mid | I190: =IFERROR(VLOOKUP(A190,Table1[#All],26,FALSE),"") -> No
A191: EMP12593 | B191: 45176 | C191: 4925 | D191: 1 | E191: 45176 | F191: Lower-Mid | G191: =IFERROR(VLOOKUP(Table4[[#This Row],[EmployeeID]],Employees!$A:$AG,33,FALSE),"") -> 4925 | H191: =_xlfn.IFS( Table4[[#This Row],[MonthlyIncome_Clean]]<=2980,"Lower", Table4[[#This Row],[MonthlyIncome_Clean]]<=5000,"Lower Mid", Table4[[#This Row],[MonthlyIncome_Clean]]<=8000,"Mid", Table4[[#This Row],[MonthlyIncome_Clean]]<=11996,"Upper Mid", Table4[[#This Row],[MonthlyIncome_Clean]]<=16000,"High" ) -> Lower Mid | I191: =IFERROR(VLOOKUP(A191,Table1[#All],26,FALSE),"") -> No
A192: EMP12756 | B192: 42751 | C192: 4918 | D192: 1 | E192: 42751 | F192: Lower-Mid | G192: =IFERROR(VLOOKUP(Table4[[#This Row],[EmployeeID]],Employees!$A:$AG,33,FALSE),"") -> 4918 | H192: =_xlfn.IFS( Table4[[#This Row],[MonthlyIncome_Clean]]<=2980,"Lower", Table4[[#This Row],[MonthlyIncome_Clean]]<=5000,"Lower Mid", Table4[[#This Row],[MonthlyIncome_Clean]]<=8000,"Mid", Table4[[#This Row],[MonthlyIncome_Clean]]<=11996,"Upper Mid", Table4[[#This Row],[MonthlyIncome_Clean]]<=16000,"High" ) -> Lower Mid | I192: =IFERROR(VLOOKUP(A192,Table1[#All],26,FALSE),"") -> No
A193: EMP12524 | B193: 45168 | C193: 11467 | D193: 3 | E193: 45168 | F193: Upper-Mid | G193: =IFERROR(VLOOKUP(Table4[[#This Row],[EmployeeID]],Employees!$A:$AG,33,FALSE),"") -> 11467 | H193: =_xlfn.IFS( Table4[[#This Row],[MonthlyIncome_Clean]]<=2980,"Lower", Table4[[#This Row],[MonthlyIncome_Clean]]<=5000,"Lower Mid", Table4[[#This Row],[MonthlyIncome_Clean]]<=8000,"Mid", Table4[[#This Row],[MonthlyIncome_Clean]]<=11996,"Upper Mid", Table4[[#This Row],[MonthlyIncome_Clean]]<=16000,"High" ) -> Upper Mid | I193: =IFERROR(VLOOKUP(A193,Table1[#All],26,FALSE),"") -> No
A194: EMP12827 | B194: 43164 | C194: 7863 | D194: 2 | E194: 43164 | F194: Mid | G194: =IFERROR(VLOOKUP(Table4[[#This Row],[EmployeeID]],Employees!$A:$AG,33,FALSE),"") -> 7863 | H194: =_xlfn.IFS( Table4[[#This Row],[MonthlyIncome_Clean]]<=2980,"Lower", Table4[[#This Row],[MonthlyIncome_Clean]]<=5000,"Lower Mid", Table4[[#This Row],[MonthlyIncome_Clean]]<=8000,"Mid", Table4[[#This Row],[MonthlyIncome_Clean]]<=11996,"Upper Mid", Table4[[#This Row],[MonthlyIncome_Clean]]<=16000,"High" ) -> Mid | I194: =IFERROR(VLOOKUP(A194,Table1[#All],26,FALSE),"") -> No
A195: EMP10106 | B195: 42945 | C195: 7861 | D195: 3 | E195: 42945 | F195: Mid | G195: =IFERROR(VLOOKUP(Table4[[#This Row],[EmployeeID]],Employees!$A:$AG,33,FALSE),"") -> 7861 | H195: =_xlfn.IFS( Table4[[#This Row],[MonthlyIncome_Clean]]<=2980,"Lower", Table4[[#This Row],[MonthlyIncome_Clean]]<=5000,"Lower Mid", Table4[[#This Row],[MonthlyIncome_Clean]]<=8000,"Mid", Table4[[#This Row],[MonthlyIncome_Clean]]<=11996,"Upper Mid", Table4[[#This Row],[MonthlyIncome_Clean]]<=16000,"High" ) -> Mid | I195: =IFERROR(VLOOKUP(A195,Table1[#All],26,FALSE),"") -> No
... A667: EMP12557 | B667: 45581 | C667: 10541 | D667: 4 | E667: 45581 | F667: Upper-Mid | G667: =IFERROR(VLOOKUP(Table4[[#This Row],[EmployeeID]],Employees!$A:$AG,33,FALSE),"") -> 10541 | H667: =_xlfn.IFS( Table4[[#This Row],[MonthlyIncome_Clean]]<=2980,"Lower", Table4[[#This Row],[MonthlyIncome_Clean]]<=5000,"Lower Mid", Table4[[#This Row],[MonthlyIncome_Clean]]<=8000,"Mid", Table4[[#This Row],[MonthlyIncome_Clean]]<=11996,"Upper Mid", Table4[[#This Row],[MonthlyIncome_Clean]]<=16000,"High" ) -> Upper Mid | I667: =IFERROR(VLOOKUP(A667,Table1[#All],26,FALSE),"") -> No
A668: EMP10667 | B668: 42063 | D668: 2 | E668: 42063 | G668: =IFERROR(VLOOKUP(Table4[[#This Row],[EmployeeID]],Employees!$A:$AG,33,FALSE),"") -> 8287.5378 | H668: =_xlfn.IFS( Table4[[#This Row],[MonthlyIncome_Clean]]<=2980,"Lower", Table4[[#This Row],[MonthlyIncome_Clean]]<=5000,"Lower Mid", Table4[[#This Row],[MonthlyIncome_Clean]]<=8000,"Mid", Table4[[#This Row],[MonthlyIncome_Clean]]<=11996,"Upper Mid", Table4[[#This Row],[MonthlyIncome_Clean]]<=16000,"High" ) -> Upper Mid | I668: =IFERROR(VLOOKUP(A668,Table1[#All],26,FALSE),"") -> No
A669: EMP11996 | B669: 43045 | C669: 10533 | D669: 3 | E669: 43045 | F669: Upper-Mid | G669: =IFERROR(VLOOKUP(Table4[[#This Row],[EmployeeID]],Employees!$A:$AG,33,FALSE),"") -> 10533 | H669: =_xlfn.IFS( Table4[[#This Row],[MonthlyIncome_Clean]]<=2980,"Lower", Table4[[#This Row],[MonthlyIncome_Clean]]<=5000,"Lower Mid", Table4[[#This Row],[MonthlyIncome_Clean]]<=8000,"Mid", Table4[[#This Row],[MonthlyIncome_Clean]]<=11996,"Upper Mid", Table4[[#This Row],[MonthlyIncome_Clean]]<=16000,"High" ) -> Upper Mid | I669: =IFERROR(VLOOKUP(A669,Table1[#All],26,FALSE),"") -> No
A670: EMP12646 | B670: 44082 | C670: 7437 | D670: 2 | E670: 44082 | F670: Mid | G670: =IFERROR(VLOOKUP(Table4[[#This Row],[EmployeeID]],Employees!$A:$AG,33,FALSE),"") -> 7437 | H670: =_xlfn.IFS( Table4[[#This Row],[MonthlyIncome_Clean]]<=2980,"Lower", Table4[[#This Row],[MonthlyIncome_Clean]]<=5000,"Lower Mid", Table4[[#This Row],[MonthlyIncome_Clean]]<=8000,"Mid", Table4[[#This Row],[MonthlyIncome_Clean]]<=11996,"Upper Mid", Table4[[#This Row],[MonthlyIncome_Clean]]<=16000,"High" ) -> Mid | I670: =IFERROR(VLOOKUP(A670,Table1[#All],26,FALSE),"") -> No
